<?xml version="1.0" encoding="utf-8"?>
<!-- ========================================================== -->
<!-- |    This document is dual dummy arm URDF file!          | -->
<!-- |    Editted by jiangjun, 2025.07.09                 | -->
<!-- ========================================================== -->
<robot name="dual_dummy">
  <!-- 定义材质颜色 -->
  <material name="silver">
    <color rgba="0.700 0.700 0.700 1.000"/>
  </material>
  <material name="red">
    <color rgba="0.8 0.2 0.2 1.0"/> <!-- 深红色 -->
  </material>
  <material name="black">
    <color rgba="0.1 0.1 0.1 1.0"/> <!-- 深黑灰色 -->
  </material>
  
  <!-- 定义固定世界关节 -->
  <link name="world"/>
  <joint name="world_joint" type="fixed">
    <parent link="world"/>
    <child link="base_plate"/>
    <origin xyz="0.0 0.0 0.025"/>
  </joint>
  
  <!-- 公共基座 -->
  <link name="base_plate">
    <inertial>
      <origin rpy="0 0 0" xyz="0 0 0"/>
      <mass value="5.0"/>
      <inertia ixx="0.1" ixy="0" ixz="0" iyy="0.1" iyz="0" izz="0.1"/>
    </inertial>
    <visual>
      <geometry>
        <box size="0.8 0.5 0.05"/>
      </geometry>
      <material name="silver"/>
    </visual>
    <collision>
      <origin rpy="0 0 0" xyz="0 0 0"/>
      <geometry>
        <box size="0.5 0.8 0.05"/>
      </geometry>
    </collision>
  </link>
  


  <!-- 机械臂连杆定义 -->
  <link name="left_base_link">
    <inertial>
      <origin rpy="0 0 0" xyz="2.242591646188575e-07 0.00022711838502637176 0.0543574942352709"/>
      <mass value="1.2152141810431654"/>
      <inertia ixx="0.002105" ixy="-0.0" ixz="0.0" iyy="0.002245" iyz="-1.1e-05" izz="0.002436"/>
    </inertial>
    <visual>
      <origin rpy="0 0 0" xyz="0 0 0"/>
      <geometry>
         <mesh filename="package://dummy2_description/meshes/base_link.stl" scale="0.001 0.001 0.001"/>
      </geometry>
      <material name="black"/>
    </visual>
    <collision>
      <origin rpy="0 0 0" xyz="0 0 0"/>
      <geometry>
         <mesh filename="package://dummy2_description/meshes/base_link.stl" scale="0.001 0.001 0.001"/>
      </geometry>
    </collision>
  </link>
  <link name="left_link1_1">
    <inertial>
      <origin rpy="0 0 0" xyz="-0.0056980705903348725 0.00648616835675352 0.012857190819102027"/>
      <mass value="0.1444690972471256"/>
      <inertia ixx="6.5e-05" ixy="2.1e-05" ixz="9e-06" iyy="5.4e-05" iyz="-1.5e-05" izz="9e-05"/>
    </inertial>
    <visual>
      <origin rpy="0 0 0" xyz="0.0 0.0 -0.096"/>
      <geometry>
         <mesh filename="package://dummy2_description/meshes/link1_1.stl" scale="0.001 0.001 0.001"/>
      </geometry>
      <material name="red"/>
    </visual>
    <collision>
      <origin rpy="0 0 0" xyz="0.0 0.0 -0.096"/>
      <geometry>
         <mesh filename="package://dummy2_description/meshes/link1_1.stl" scale="0.001 0.001 0.001"/>
      </geometry>
    </collision>
  </link>
  <link name="left_link2_1">
    <inertial>
      <origin rpy="0 0 0" xyz="0.0188447417509659 0.0019829653147296275 0.08367138108787778"/>
      <mass value="0.6521077215074461"/>
      <inertia ixx="0.002179" ixy="-1e-06" ixz="0.000265" iyy="0.002318" iyz="2.2e-05" izz="0.000411"/>
    </inertial>
    <visual>
      <origin rpy="0 0 0" xyz="0.011639 -0.034477 -0.1245"/>
      <geometry>
         <mesh filename="package://dummy2_description/meshes/link2_1.stl" scale="0.001 0.001 0.001"/>
      </geometry>
      <material name="black"/>
    </visual>
    <collision>
      <origin rpy="0 0 0" xyz="0.011639 -0.034477 -0.1245"/>
      <geometry>
         <mesh filename="package://dummy2_description/meshes/link2_1.stl" scale="0.001 0.001 0.001"/>
      </geometry>
    </collision>
  </link>
  <link name="left_link3_1">
    <inertial>
      <origin rpy="0 0 0" xyz="-0.01071065579982854 -0.027860026044143744 0.04896369644132431"/>
      <mass value="0.6005346433244714"/>
      <inertia ixx="0.000823" ixy="-4e-05" ixz="8.7e-05" iyy="0.000697" iyz="0.000126" izz="0.000535"/>
    </inertial>
    <visual>
      <origin rpy="0 0 0" xyz="-0.024511 -0.034477 -0.2925"/>
      <geometry>
         <mesh filename="package://dummy2_description/meshes/link3_1.stl" scale="0.001 0.001 0.001"/>
      </geometry>
      <material name="red"/>
    </visual>
    <collision>
      <origin rpy="0 0 0" xyz="-0.024511 -0.034477 -0.2925"/>
      <geometry>
         <mesh filename="package://dummy2_description/meshes/link3_1.stl" scale="0.001 0.001 0.001"/>
      </geometry>
    </collision>
  </link>
  <link name="left_link4_1">
    <inertial>
      <origin rpy="0 0 0" xyz="-0.0052376144149527196 0.0600375883820652 0.0005874969147224296"/>
      <mass value="0.1580312221089852"/>
      <inertia ixx="0.000624" ixy="4e-05" ixz="3e-06" iyy="0.000202" iyz="-5e-06" izz="0.000688"/>
    </inertial>
    <visual>
      <origin rpy="0 0 0" xyz="-0.011349 -0.038577 -0.354967"/>
      <geometry>
         <mesh filename="package://dummy2_description/meshes/link4_1.stl" scale="0.001 0.001 0.001"/>
      </geometry>
      <material name="black"/>
    </visual>
    <collision>
      <origin rpy="0 0 0" xyz="-0.011349 -0.038577 -0.354967"/>
      <geometry>
         <mesh filename="package://dummy2_description/meshes/link4_1.stl" scale="0.001 0.001 0.001"/>
      </geometry>
    </collision>
  </link>
  <link name="left_link5_1">
    <inertial>
      <origin rpy="0 0 0" xyz="-0.014439500295566867 0.07274346111500346 -0.0007483346369849819"/>
      <mass value="0.07858738652766984"/>
      <inertia ixx="0.00089" ixy="0.000144" ixz="-4e-06" iyy="0.000343" iyz="6e-06" izz="0.000973"/>
    </inertial>
    <visual>
      <origin rpy="0 0 0" xyz="-0.032649 -0.148577 -0.354967"/>
      <geometry>
         <mesh filename="package://dummy2_description/meshes/link5_1.stl" scale="0.001 0.001 0.001"/>
      </geometry>
      <material name="red"/>
    </visual>
    <collision>
      <origin rpy="0 0 0" xyz="-0.032649 -0.148577 -0.354967"/>
      <geometry>
         <mesh filename="package://dummy2_description/meshes/link5_1.stl" scale="0.001 0.001 0.001"/>
      </geometry>
    </collision>
  </link>
  <link name="left_link6_1">
    <inertial>
      <origin rpy="0 0 0" xyz="5.087622746753444e-05 0.04245066924408897 6.811081131086194e-05"/>
      <mass value="0.0604072405055537"/>
      <inertia ixx="0.000334" ixy="-2e-06" ixz="-1e-06" iyy="0.000382" iyz="2e-06" izz="0.000521"/>
    </inertial>
    <visual>
      <origin rpy="0 0 0" xyz="-0.012827 -0.268077 -0.353741"/>
      <geometry>
         <mesh filename="package://dummy2_description/meshes/link6_1.stl" scale="0.001 0.001 0.001"/>
      </geometry>
      <material name="black"/>
    </visual>
    <collision>
      <origin rpy="0 0 0" xyz="-0.012827 -0.268077 -0.353741"/>
      <geometry>
         <mesh filename="package://dummy2_description/meshes/link6_1.stl" scale="0.001 0.001 0.001"/>
      </geometry>
    </collision>
  </link>
  <link name="left_figer1_1">
    <inertial>
      <origin rpy="0 0 0" xyz="-0.001013816286429263 0.017871453686335137 -9.360034337241308e-05"/>
      <mass value="0.0122978780886348"/>
      <inertia ixx="8e-06" ixy="1e-06" ixz="0.0" iyy="2e-06" iyz="0.0" izz="8e-06"/>
    </inertial>
    <visual>
      <origin rpy="0 0 0" xyz="-0.025651 -0.342539 -0.353641"/>
      <geometry>
         <mesh filename="package://dummy2_description/meshes/figer1_1.stl" scale="0.001 0.001 0.001"/>
      </geometry>
      <material name="black"/>
    </visual>
    <collision>
      <origin rpy="0 0 0" xyz="-0.025651 -0.342539 -0.353641"/>
      <geometry>
         <mesh filename="package://dummy2_description/meshes/figer1_1.stl" scale="0.001 0.001 0.001"/>
      </geometry>
    </collision>
  </link>
  <link name="left_figer2_1">
    <inertial>
      <origin rpy="0 0 0" xyz="0.001014115315322053 0.01787145295991821 9.418612516776115e-05"/>
      <mass value="0.012297878145578977"/>
      <inertia ixx="8e-06" ixy="-1e-06" ixz="0.0" iyy="2e-06" iyz="-0.0" izz="8e-06"/>
    </inertial>
    <visual>
      <origin rpy="0 0 0" xyz="-0.000651 -0.342539 -0.353741"/>
      <geometry>
         <mesh filename="package://dummy2_description/meshes/figer2_1.stl" scale="0.001 0.001 0.001"/>
      </geometry>
      <material name="black"/>
    </visual>
    <collision>
      <origin rpy="0 0 0" xyz="-0.000651 -0.342539 -0.353741"/>
      <geometry>
         <mesh filename="package://dummy2_description/meshes/figer2_1.stl" scale="0.001 0.001 0.001"/>
      </geometry>
    </collision>
  </link>
 

  <!-- 机械臂关节定义 -->

  <joint name="left_base_joint" type="fixed">
    <origin rpy="0 0 0" xyz="-0.3 -0.2 0.025"/> <!-- 机械臂偏移位置 -->
    <parent link="base_plate"/>
    <child link="left_base_link"/>
  </joint>
  <joint name="left_joint1" type="revolute">
    <origin rpy="0 0 0" xyz="0.0 0.0 0.096"/>
    <parent link="left_base_link"/>
    <child link="left_link1_1"/>
    <axis xyz="0.0 -0.0 -1.0"/>
    <limit effort="100" lower="-3.001966" upper="3.001966" velocity="100"/>

  </joint>
  <joint name="left_joint2" type="revolute">
    <origin rpy="0 0 0" xyz="-0.011639 0.034477 0.0285"/>
    <parent link="left_link1_1"/>
    <child link="left_link2_1"/>
    <axis xyz="1.0 0.0 -0.0"/>
    <limit effort="100" lower="-1.570796" upper="1.308997" velocity="100"/>
    <dynamics damping="1" friction="0.05"/> 
  </joint>
  <joint name="left_joint3" type="revolute">
    <origin rpy="0 0 0" xyz="0.03615 0.0 0.168"/>
    <parent link="left_link2_1"/>
    <child link="left_link3_1"/>
    <axis xyz="-1.0 -0.0 -0.0"/>
    <limit effort="200" lower="-1.500983" upper="1.570796" velocity="100"/>

  </joint>
  <joint name="left_joint4" type="revolute">
    <origin rpy="0 0 0" xyz="-0.013162 0.0041 0.062467"/>
    <parent link="left_link3_1"/>
    <child link="left_link4_1"/>
    <axis xyz="0.0 -1.0 0.0"/>
    <limit effort="100" lower="-3.141593" upper="3.141593" velocity="100"/>

  </joint>
  <joint name="left_joint5" type="revolute">
    <origin rpy="0 0 0" xyz="0.0213 0.11 0.0"/>
    <parent link="left_link4_1"/>
    <child link="left_link5_1"/>
    <axis xyz="-1.0 -0.0 -0.0"/>
    <limit effort="200" lower="-1.919862" upper="2.094395" velocity="100"/>
    <dynamics damping="0.6" friction="0.06"/> 
  </joint>
  <joint name="left_joint6" type="revolute">
    <origin rpy="0 0 0" xyz="-0.019822 0.1195 -0.001226"/>
    <parent link="left_link5_1"/>
    <child link="left_link6_1"/>
    <axis xyz="0.0 -1.0 -0.0"/>
    <limit effort="100" lower="-3.141593" upper="3.141593" velocity="100"/>

  </joint>
  <joint name="left_figer1" type="prismatic">
    <origin rpy="0 0 0" xyz="0.012824 0.074462 -0.0001"/>
    <parent link="left_link6_1"/>
    <child link="left_figer1_1"/>
    <axis xyz="1.0 0.0 0.0"/>
    <limit effort="100" lower="0.0" upper="0.028" velocity="100"/>

  </joint>
  <joint name="left_figer2" type="prismatic">
    <origin rpy="0 0 0" xyz="-0.012176 0.074462 0.0"/>
    <parent link="left_link6_1"/>
    <child link="left_figer2_1"/>
    <axis xyz="1.0 0.0 0.0"/>
    <limit effort="100" lower="-0.028" upper="0.0" velocity="100"/>

  </joint>
   

  <!-- 机械臂连杆定义 -->
  <link name="right_base_link">
    <inertial>
      <origin rpy="0 0 0" xyz="2.242591646188575e-07 0.00022711838502637176 0.0543574942352709"/>
      <mass value="1.2152141810431654"/>
      <inertia ixx="0.002105" ixy="-0.0" ixz="0.0" iyy="0.002245" iyz="-1.1e-05" izz="0.002436"/>
    </inertial>
    <visual>
      <origin rpy="0 0 0" xyz="0 0 0"/>
      <geometry>
         <mesh filename="package://dummy2_description/meshes/base_link.stl" scale="0.001 0.001 0.001"/>
      </geometry>
      <material name="black"/>
    </visual>
    <collision>
      <origin rpy="0 0 0" xyz="0 0 0"/>
      <geometry>
         <mesh filename="package://dummy2_description/meshes/base_link.stl" scale="0.001 0.001 0.001"/>
      </geometry>
    </collision>
  </link>
  <link name="right_link1_1">
    <inertial>
      <origin rpy="0 0 0" xyz="-0.0056980705903348725 0.00648616835675352 0.012857190819102027"/>
      <mass value="0.1444690972471256"/>
      <inertia ixx="6.5e-05" ixy="2.1e-05" ixz="9e-06" iyy="5.4e-05" iyz="-1.5e-05" izz="9e-05"/>
    </inertial>
    <visual>
      <origin rpy="0 0 0" xyz="0.0 0.0 -0.096"/>
      <geometry>
         <mesh filename="package://dummy2_description/meshes/link1_1.stl" scale="0.001 0.001 0.001"/>
      </geometry>
      <material name="red"/>
    </visual>
    <collision>
      <origin rpy="0 0 0" xyz="0.0 0.0 -0.096"/>
      <geometry>
         <mesh filename="package://dummy2_description/meshes/link1_1.stl" scale="0.001 0.001 0.001"/>
      </geometry>
    </collision>
  </link>
  <link name="right_link2_1">
    <inertial>
      <origin rpy="0 0 0" xyz="0.0188447417509659 0.0019829653147296275 0.08367138108787778"/>
      <mass value="0.6521077215074461"/>
      <inertia ixx="0.002179" ixy="-1e-06" ixz="0.000265" iyy="0.002318" iyz="2.2e-05" izz="0.000411"/>
    </inertial>
    <visual>
      <origin rpy="0 0 0" xyz="0.011639 -0.034477 -0.1245"/>
      <geometry>
         <mesh filename="package://dummy2_description/meshes/link2_1.stl" scale="0.001 0.001 0.001"/>
      </geometry>
      <material name="black"/>
    </visual>
    <collision>
      <origin rpy="0 0 0" xyz="0.011639 -0.034477 -0.1245"/>
      <geometry>
         <mesh filename="package://dummy2_description/meshes/link2_1.stl" scale="0.001 0.001 0.001"/>
      </geometry>
    </collision>
  </link>
  <link name="right_link3_1">
    <inertial>
      <origin rpy="0 0 0" xyz="-0.01071065579982854 -0.027860026044143744 0.04896369644132431"/>
      <mass value="0.6005346433244714"/>
      <inertia ixx="0.000823" ixy="-4e-05" ixz="8.7e-05" iyy="0.000697" iyz="0.000126" izz="0.000535"/>
    </inertial>
    <visual>
      <origin rpy="0 0 0" xyz="-0.024511 -0.034477 -0.2925"/>
      <geometry>
         <mesh filename="package://dummy2_description/meshes/link3_1.stl" scale="0.001 0.001 0.001"/>
      </geometry>
      <material name="red"/>
    </visual>
    <collision>
      <origin rpy="0 0 0" xyz="-0.024511 -0.034477 -0.2925"/>
      <geometry>
         <mesh filename="package://dummy2_description/meshes/link3_1.stl" scale="0.001 0.001 0.001"/>
      </geometry>
    </collision>
  </link>
  <link name="right_link4_1">
    <inertial>
      <origin rpy="0 0 0" xyz="-0.0052376144149527196 0.0600375883820652 0.0005874969147224296"/>
      <mass value="0.1580312221089852"/>
      <inertia ixx="0.000624" ixy="4e-05" ixz="3e-06" iyy="0.000202" iyz="-5e-06" izz="0.000688"/>
    </inertial>
    <visual>
      <origin rpy="0 0 0" xyz="-0.011349 -0.038577 -0.354967"/>
      <geometry>
         <mesh filename="package://dummy2_description/meshes/link4_1.stl" scale="0.001 0.001 0.001"/>
      </geometry>
      <material name="black"/>
    </visual>
    <collision>
      <origin rpy="0 0 0" xyz="-0.011349 -0.038577 -0.354967"/>
      <geometry>
         <mesh filename="package://dummy2_description/meshes/link4_1.stl" scale="0.001 0.001 0.001"/>
      </geometry>
    </collision>
  </link>
  <link name="right_link5_1">
    <inertial>
      <origin rpy="0 0 0" xyz="-0.014439500295566867 0.07274346111500346 -0.0007483346369849819"/>
      <mass value="0.07858738652766984"/>
      <inertia ixx="0.00089" ixy="0.000144" ixz="-4e-06" iyy="0.000343" iyz="6e-06" izz="0.000973"/>
    </inertial>
    <visual>
      <origin rpy="0 0 0" xyz="-0.032649 -0.148577 -0.354967"/>
      <geometry>
         <mesh filename="package://dummy2_description/meshes/link5_1.stl" scale="0.001 0.001 0.001"/>
      </geometry>
      <material name="red"/>
    </visual>
    <collision>
      <origin rpy="0 0 0" xyz="-0.032649 -0.148577 -0.354967"/>
      <geometry>
         <mesh filename="package://dummy2_description/meshes/link5_1.stl" scale="0.001 0.001 0.001"/>
      </geometry>
    </collision>
  </link>
  <link name="right_link6_1">
    <inertial>
      <origin rpy="0 0 0" xyz="5.087622746753444e-05 0.04245066924408897 6.811081131086194e-05"/>
      <mass value="0.0604072405055537"/>
      <inertia ixx="0.000334" ixy="-2e-06" ixz="-1e-06" iyy="0.000382" iyz="2e-06" izz="0.000521"/>
    </inertial>
    <visual>
      <origin rpy="0 0 0" xyz="-0.012827 -0.268077 -0.353741"/>
      <geometry>
         <mesh filename="package://dummy2_description/meshes/link6_1.stl" scale="0.001 0.001 0.001"/>
      </geometry>
      <material name="black"/>
    </visual>
    <collision>
      <origin rpy="0 0 0" xyz="-0.012827 -0.268077 -0.353741"/>
      <geometry>
         <mesh filename="package://dummy2_description/meshes/link6_1.stl" scale="0.001 0.001 0.001"/>
      </geometry>
    </collision>
  </link>
  <link name="right_figer1_1">
    <inertial>
      <origin rpy="0 0 0" xyz="-0.001013816286429263 0.017871453686335137 -9.360034337241308e-05"/>
      <mass value="0.0422978780886348"/>
      <inertia ixx="8e-06" ixy="1e-06" ixz="0.0" iyy="2e-06" iyz="0.0" izz="8e-06"/>
    </inertial>
    <visual>
      <origin rpy="0 0 0" xyz="-0.025651 -0.342539 -0.353641"/>
      <geometry>
         <mesh filename="package://dummy2_description/meshes/figer1_1.stl" scale="0.001 0.001 0.001"/>
      </geometry>
      <material name="black"/>
    </visual>
    <collision>
      <origin rpy="0 0 0" xyz="-0.025651 -0.342539 -0.353641"/>
      <geometry>
         <mesh filename="package://dummy2_description/meshes/figer1_1.stl" scale="0.001 0.001 0.001"/>
      </geometry>
    </collision>
  </link>
  <link name="right_figer2_1">
    <inertial>
      <origin rpy="0 0 0" xyz="0.001014115315322053 0.01787145295991821 9.418612516776115e-05"/>
      <mass value="0.042297878145578977"/>
      <inertia ixx="8e-06" ixy="-1e-06" ixz="0.0" iyy="2e-06" iyz="-0.0" izz="8e-06"/>
    </inertial>
    <visual>
      <origin rpy="0 0 0" xyz="-0.000651 -0.342539 -0.353741"/>
      <geometry>
         <mesh filename="package://dummy2_description/meshes/figer2_1.stl" scale="0.001 0.001 0.001"/>
      </geometry>
      <material name="black"/>
    </visual>
    <collision>
      <origin rpy="0 0 0" xyz="-0.000651 -0.342539 -0.353741"/>
      <geometry>
         <mesh filename="package://dummy2_description/meshes/figer2_1.stl" scale="0.001 0.001 0.001"/>
      </geometry>
    </collision>
  </link>

  <!-- 机械臂关节定义 -->

  <joint name="right_base_joint" type="fixed">
    <origin rpy="0 0 0" xyz="0.3 -0.2 0.025"/> <!-- 机械臂偏移位置 -->
    <parent link="base_plate"/>
    <child link="right_base_link"/>
  </joint>
  <joint name="right_joint1" type="revolute">
    <origin rpy="0 0 0" xyz="0.0 0.0 0.096"/>
    <parent link="right_base_link"/>
    <child link="right_link1_1"/>
    <axis xyz="0.0 -0.0 -1.0"/>
    <limit effort="100" lower="-3.001966" upper="3.001966" velocity="100"/>

  </joint>
  <joint name="right_joint2" type="revolute">
    <origin rpy="0 0 0" xyz="-0.011639 0.034477 0.0285"/>
    <parent link="right_link1_1"/>
    <child link="right_link2_1"/>
    <axis xyz="1.0 0.0 -0.0"/>
    <limit effort="100" lower="-1.570796" upper="1.308997" velocity="100"/>
    <dynamics damping="1" friction="0.05"/> 
  </joint>
  <joint name="right_joint3" type="revolute">
    <origin rpy="0 0 0" xyz="0.03615 0.0 0.168"/>
    <parent link="right_link2_1"/>
    <child link="right_link3_1"/>
    <axis xyz="-1.0 -0.0 -0.0"/>
    <limit effort="200" lower="-1.500983" upper="1.570796" velocity="100"/>

  </joint>
  <joint name="right_joint4" type="revolute">
    <origin rpy="0 0 0" xyz="-0.013162 0.0041 0.062467"/>
    <parent link="right_link3_1"/>
    <child link="right_link4_1"/>
    <axis xyz="0.0 -1.0 0.0"/>
    <limit effort="100" lower="-3.141593" upper="3.141593" velocity="100"/>

  </joint>
  <joint name="right_joint5" type="revolute">
    <origin rpy="0 0 0" xyz="0.0213 0.11 0.0"/>
    <parent link="right_link4_1"/>
    <child link="right_link5_1"/>
    <axis xyz="-1.0 -0.0 -0.0"/>
    <limit effort="200" lower="-1.919862" upper="2.094395" velocity="100"/>
    <dynamics damping="0.6" friction="0.06"/> 
  </joint>
  <joint name="right_joint6" type="revolute">
    <origin rpy="0 0 0" xyz="-0.019822 0.1195 -0.001226"/>
    <parent link="right_link5_1"/>
    <child link="right_link6_1"/>
    <axis xyz="0.0 -1.0 -0.0"/>
    <limit effort="100" lower="-3.141593" upper="3.141593" velocity="100"/>

  </joint>
  <joint name="right_figer1" type="prismatic">
    <origin rpy="0 0 0" xyz="0.012824 0.074462 -0.0001"/>
    <parent link="right_link6_1"/>
    <child link="right_figer1_1"/>
    <axis xyz="1.0 0.0 0.0"/>
    <limit effort="100" lower="0.0" upper="0.028" velocity="100"/>

  </joint>
  <joint name="right_figer2" type="prismatic">
    <origin rpy="0 0 0" xyz="-0.012176 0.074462 0.0"/>
    <parent link="right_link6_1"/>
    <child link="right_figer2_1"/>
    <axis xyz="-1.0 0.0 0.0"/>
    <limit effort="100" lower="0.0" upper="0.028" velocity="100"/>
    
  </joint>

  

</robot>
